Workbook

Sheet Assumptions
A1: Integrated Model Assumptions — Bear / Base / Bull Drivers, FY2026E-FY2030E
A3: ACTIVE SCENARIO (type Bear / Base / Bull): | B3: Base
A5: Bear Case drivers
A6: Fiscal Year | B6: 2026E | C6: 2027E | D6: 2028E | E6: 2029E | F6: 2030E
A7: Net revenue growth % | B7: -0.03 | C7: 0.01 | D7: 0.02 | E7: 0.02 | F7: 0.02
A8: Efficiency ratio (Opex / Revenue) | B8: 0.68 | C8: 0.67 | D8: 0.66 | E8: 0.66 | F8: 0.66
A9: Effective tax rate | B9: 0.23
A10: Total payout ratio (div + buyback / NI to common) | B10: 0.55
A11: Balance sheet / RWA growth rate (equity retention driver) | B11: 0.02
A12: Terminal growth rate (Gordon growth, post-2030E) | B12: 0.02
A13: Cost of equity (CAPM) | B13: 0.115
A15: Base Case drivers
A16: Fiscal Year | B16: 2026E | C16: 2027E | D16: 2028E | E16: 2029E | F16: 2030E
A17: Net revenue growth % | B17: 0.06 | C17: 0.05 | D17: 0.05 | E17: 0.045 | F17: 0.045
A18: Efficiency ratio (Opex / Revenue) | B18: 0.63 | C18: 0.62 | D18: 0.615 | E18: 0.61 | F18: 0.61
A19: Effective tax rate | B19: 0.22
A20: Total payout ratio (div + buyback / NI to common) | B20: 0.65
A21: Balance sheet / RWA growth rate (equity retention driver) | B21: 0.04
A22: Terminal growth rate (Gordon growth, post-2030E) | B22: 0.03
A23: Cost of equity (CAPM) | B23: 0.108
A25: Bull Case drivers
A26: Fiscal Year | B26: 2026E | C26: 2027E | D26: 2028E | E26: 2029E | F26: 2030E
A27: Net revenue growth % | B27: 0.11 | C27: 0.09 | D27: 0.08 | E27: 0.07 | F27: 0.065
A28: Efficiency ratio (Opex / Revenue) | B28: 0.6 | C28: 0.585 | D28: 0.575 | E28: 0.57 | F28: 0.565
A29: Effective tax rate | B29: 0.21
A30: Total payout ratio (div + buyback / NI to common) | B30: 0.75
A31: Balance sheet / RWA growth rate (equity retention driver) | B31: 0.06
A32: Terminal growth rate (Gordon growth, post-2030E) | B32: 0.035
A33: Cost of equity (CAPM) | B33: 0.101
A36: ACTIVE DRIVERS (auto-selected from B3)
A37: Fiscal Year | B37: 2026E | C37: 2027E | D37: 2028E | E37: 2029E | F37: 2030E
A38: Net revenue growth % | B38: =IF($B$3="Bear",B7,IF($B$3="Base",B17,B27)) -> 0.06 | C38: =IF($B$3="Bear",C7,IF($B$3="Base",C17,C27)) -> 0.05 | D38: =IF($B$3="Bear",D7,IF($B$3="Base",D17,D27)) -> 0.05 | E38: =IF($B$3="Bear",E7,IF($B$3="Base",E17,E27)) -> 0.045 | F38: =IF($B$3="Bear",F7,IF($B$3="Base",F17,F27)) -> 0.045
A39: Efficiency ratio | B39: =IF($B$3="Bear",B8,IF($B$3="Base",B18,B28)) -> 0.63 | C39: =IF($B$3="Bear",C8,IF($B$3="Base",C18,C28)) -> 0.62 | D39: =IF($B$3="Bear",D8,IF($B$3="Base",D18,D28)) -> 0.615 | E39: =IF($B$3="Bear",E8,IF($B$3="Base",E18,E28)) -> 0.61 | F39: =IF($B$3="Bear",F8,IF($B$3="Base",F18,F28)) -> 0.61
A40: Effective tax rate | B40: =IF($B$3="Bear",B9,IF($B$3="Base",B19,B29)) -> 0.22
A41: Total payout ratio | B41: =IF($B$3="Bear",B10,IF($B$3="Base",B20,B30)) -> 0.65
A42: Balance sheet / RWA growth (equity retention driver) | B42: =IF($B$3="Bear",B11,IF($B$3="Base",B21,B31)) -> 0.04
A43: Terminal growth rate | B43: =IF($B$3="Bear",B12,IF($B$3="Base",B22,B32)) -> 0.03
A44: Cost of equity (CAPM) | B44: =IF($B$3="Bear",B13,IF($B$3="Base",B23,B33)) -> 0.108
A46: Preferred dividends, held flat ($mm/yr) | B46: 900
A47: Current Price / Book multiple (buyback execution price proxy) | B47: 2.8582494
...

Sheet Income Statement Proj.
A1: Projected Income Statement, FY2026E-FY2030E ($ in millions, except per share)
A4: ($ in millions except per share; 2025A shown for reference)
A5: Fiscal Year | B5: 2025A | C5: 2026E | D5: 2027E | E5: 2028E | F5: 2029E | G5: 2030E
A6: Net revenues | B6: 58280 | C6: =B6*(1+Assumptions!B38) -> 61776.8 | D6: =C6*(1+Assumptions!C38) -> 64865.64 | E6: =D6*(1+Assumptions!D38) -> 68108.922 | F6: =E6*(1+Assumptions!E38) -> 71173.823 | G6: =F6*(1+Assumptions!F38) -> 74376.646
A7: % growth YoY | C7: =Assumptions!B38 -> 0.06 | D7: =Assumptions!C38 -> 0.05 | E7: =Assumptions!D38 -> 0.05 | F7: =Assumptions!E38 -> 0.045 | G7: =Assumptions!F38 -> 0.045
A8: Operating expenses | C8: =C6*Assumptions!B39 -> 38919.384 | D8: =D6*Assumptions!C39 -> 40216.697 | E8: =E6*Assumptions!D39 -> 41886.987 | F8: =F6*Assumptions!E39 -> 43416.032 | G8: =G6*Assumptions!F39 -> 45369.754
A9: Pre-tax earnings | C9: =C6-C8 -> 22857.416 | D9: =D6-D8 -> 24648.943 | E9: =E6-E8 -> 26221.935 | F9: =F6-F8 -> 27757.791 | G9: =G6-G8 -> 29006.892
A10: Provision for taxes | C10: =C9*Assumptions!$B$40 -> 5028.6315 | D10: =D9*Assumptions!$B$40 -> 5422.7675 | E10: =E9*Assumptions!$B$40 -> 5768.8257 | F10: =F9*Assumptions!$B$40 -> 6106.7141 | G10: =G9*Assumptions!$B$40 -> 6381.5162
A11: Net earnings | B11: 17180 | C11: =C9-C10 -> 17828.784 | D11: =D9-D10 -> 19226.176 | E11: =E9-E10 -> 20453.109 | F11: =F9-F10 -> 21651.077 | G11: =G9-G10 -> 22625.376
A12: Less: preferred dividends | B12: -900 | C12: =-Assumptions!$B$46 -> -900 | D12: =-Assumptions!$B$46 -> -900 | E12: =-Assumptions!$B$46 -> -900 | F12: =-Assumptions!$B$46 -> -900 | G12: =-Assumptions!$B$46 -> -900
A13: Net earnings applicable to common shareholders | B13: =B11+B12 -> 16280 | C13: =C11+C12 -> 16928.784 | D13: =D11+D12 -> 18326.176 | E13: =E11+E12 -> 19553.109 | F13: =F11+F12 -> 20751.077 | G13: =G11+G12 -> 21725.376
A14: Diluted weighted-average shares (mm) [linked] | B14: 300.6 | C14: ='Capital & Shares'!C16 -> 296.72436 | D14: ='Capital & Shares'!D16 -> 288.97487 | E14: ='Capital & Shares'!E16 -> 281.29255 | F14: ='Capital & Shares'!F16 -> 273.76277 | G14: ='Capital & Shares'!G16 -> 266.45553
A15: Diluted EPS | B15: =B13/B14 -> 54.15835 | C15: =C13/C14 -> 57.052224 | D15: =D13/D14 -> 63.417888 | E15: =E13/E14 -> 69.511651 | F15: =F13/F14 -> 75.799486 | G15: =G13/G14 -> 81.534714
A16: Net margin | B16: =B11/B6 -> 0.2947838 | C16: =C11/C6 -> 0.2886 | D16: =D11/D6 -> 0.2964 | E16: =E11/E6 -> 0.3003 | F16: =F11/F6 -> 0.3042 | G16: =G11/G6 -> 0.3042
A18: Formula flow: Net revenues grow off Assumptions active drivers -> Opex = Revenue x efficiency ratio
A19: -> Pre-tax = Revenue - Opex -> Tax = Pre-tax x tax rate -> Net earnings -> less preferred dividends
A20: -> Net earnings to common. Diluted shares link FROM the Capital & Shares tab (green cells = links).
A21: No circularity: shares/BVPS depend on Net earnings to common, which is computed independently above.

Sheet Capital & Shares
A1: Common Equity & Diluted Shares Roll-Forward, FY2026E-FY2030E
A4: ($ in millions except per share; shares in millions; 2025A shown for reference)
A5: Fiscal Year | B5: 2025A | C5: 2026E | D5: 2027E | E5: 2028E | F5: 2029E | G5: 2030E
A6: Beginning common equity | C6: =B11 -> 107494.6 | D6: =C11 -> 113419.67 | E6: =D11 -> 119833.84 | F6: =E11 -> 126677.42 | G6: =F11 -> 133940.3
A7: Net earnings applicable to common [linked] | C7: ='Income Statement Proj.'!C13 -> 16928.784 | D7: ='Income Statement Proj.'!D13 -> 18326.176 | E7: ='Income Statement Proj.'!E13 -> 19553.109 | F7: ='Income Statement Proj.'!F13 -> 20751.077 | G7: ='Income Statement Proj.'!G13 -> 21725.376
A8: Total capital returned (payout ratio x NI to common) | C8: =C7*Assumptions!$B$41 -> 11003.71 | D8: =D7*Assumptions!$B$41 -> 11912.014 | E8: =E7*Assumptions!$B$41 -> 12709.521 | F8: =F7*Assumptions!$B$41 -> 13488.2 | G8: =G7*Assumptions!$B$41 -> 14121.494
A9: Common dividends | C9: =C8*Assumptions!$B$48 -> 3081.0388 | D9: =D8*Assumptions!$B$48 -> 3335.364 | E9: =E8*Assumptions!$B$48 -> 3558.6659 | F9: =F8*Assumptions!$B$48 -> 3776.696 | G9: =G8*Assumptions!$B$48 -> 3954.0184
A10: Share repurchases ($) | C10: =C8-C9 -> 7922.6711 | D10: =D8-D9 -> 8576.6502 | E10: =E8-E9 -> 9150.8551 | F10: =F8-F9 -> 9711.5041 | G10: =G8-G9 -> 10167.476
A11: Ending common equity | B11: 107494.6 | C11: =C6+C7-C8 -> 113419.67 | D11: =D6+D7-D8 -> 119833.84 | E11: =E6+E7-E8 -> 126677.42 | F11: =F6+F7-F8 -> 133940.3 | G11: =G6+G7-G8 -> 141544.18
A12: Beginning diluted shares (mm) | C12: =B15 -> 300.6 | D12: =C15 -> 292.84871 | E12: =D15 -> 285.10102 | F12: =E15 -> 277.48407 | G12: =F15 -> 270.04146
A13: Assumed repurchase price / share | C13: =(C6/C12)*Assumptions!$B$47 -> 1022.1104 | D13: =(D6/D12)*Assumptions!$B$47 -> 1106.9938 | E13: =(E6/E12)*Assumptions!$B$47 -> 1201.3812 | F13: =(F6/F12)*Assumptions!$B$47 -> 1304.8521 | G13: =(G6/G12)*Assumptions!$B$47 -> 1417.6889
A14: Shares repurchased (mm) | C14: =C10/C13 -> 7.7512872 | D14: =D10/D13 -> 7.7476946 | E14: =E10/E13 -> 7.6169457 | F14: =F10/F13 -> 7.442609 | G14: =G10/G13 -> 7.1718666
A15: Ending diluted shares (mm) | B15: 300.6 | C15: =C12-C14 -> 292.84871 | D15: =D12-D14 -> 285.10102 | E15: =E12-E14 -> 277.48407 | F15: =F12-F14 -> 270.04146 | G15: =G12-G14 -> 262.8696
A16: Average diluted shares (mm) [feeds EPS] | C16: =AVERAGE(C12,C15) -> 296.72436 | D16: =AVERAGE(D12,D15) -> 288.97487 | E16: =AVERAGE(E12,E15) -> 281.29255 | F16: =AVERAGE(F12,F15) -> 273.76277 | G16: =AVERAGE(G12,G15) -> 266.45553
A17: Book value per share (ending) | B17: =B11/B15 -> 357.60013 | C17: =C11/C15 -> 387.29784 | D17: =D11/D15 -> 420.32062 | E17: =E11/E15 -> 456.52143 | F17: =F11/F15 -> 495.99902 | G17: =G11/G15 -> 538.45779
A18: Return on average common equity | C18: =C7/AVERAGE(C6,C11) -> 0.15326112 | D18: =D7/AVERAGE(D6,D11) -> 0.15713526 | E18: =E7/AVERAGE(E6,E11) -> 0.15863867 | F18: =F7/AVERAGE(F6,F11) -> 0.15924532 | G18: =G7/AVERAGE(G6,G11) -> 0.15772486
A19: Dividend per share | C19: =C9/C16 -> 10.383505 | D19: =D9/D16 -> 11.542056 | E19: =E9/E16 -> 12.651121 | F19: =F9/F16 -> 13.795506 | G19: =G9/G16 -> 14.839318
A21: Equity roll-forward: Ending equity = Beginning equity + Net income to common - Total capital
A22: returned (dividends + buybacks). Buyback $ / assumed repurchase price (BVPS x current P/B multiple)
A23: shares repurchased -> ending shares -> bvps and roe fall out mechanically. average shares feed
A24: diluted EPS on the Income Statement Proj. tab (see green-linked cells there).

Sheet Scenario Summary
A1: Bull / Base / Bear — Full 5-Year Projection Comparison, FY2026E-FY2030E
B3: Bear Case | H3: Base Case | N3: Bull Case
B4: 2026E | C4: 2027E | D4: 2028E | E4: 2029E | F4: 2030E | H4: 2026E | I4: 2027E | J4: 2028E | K4: 2029E | L4: 2030E | N4: 2026E | O4: 2027E | P4: 2028E | Q4: 2029E | R4: 2030E
A5: Net revenues ($mm) | B5: =58280*(1+Assumptions!B7) -> 56531.6 | C5: =B5*(1+Assumptions!C7) -> 57096.916 | D5: =C5*(1+Assumptions!D7) -> 58238.854 | E5: =D5*(1+Assumptions!E7) -> 59403.631 | F5: =E5*(1+Assumptions!F7) -> 60591.704 | H5: =58280*(1+Assumptions!B17) -> 61776.8 | I5: =H5*(1+Assumptions!C17) -> 64865.64 | J5: =I5*(1+Assumptions!D17) -> 68108.922 | K5: =J5*(1+Assumptions!E17) -> 71173.823 | L5: =K5*(1+Assumptions!F17) -> 74376.646 | N5: =58280*(1+Assumptions!B27) -> 64690.8 | O5: =N5*(1+Assumptions!C27) -> 70512.972 | P5: =O5*(1+Assumptions!D27) -> 76154.01 | Q5: =P5*(1+Assumptions!E27) -> 81484.79 | R5: =Q5*(1+Assumptions!F27) -> 86781.302
A6: Net earnings to common ($mm) | B6: =(B5*(1-Assumptions!B8))*(1-Assumptions!$B$9)-Assumptions!$B$46 -> 13029.386 | C6: =(C5*(1-Assumptions!C8))*(1-Assumptions!$B$9)-Assumptions!$B$46 -> 13608.326 | D6: =(D5*(1-Assumptions!D8))*(1-Assumptions!$B$9)-Assumptions!$B$46 -> 14346.932 | E6: =(E5*(1-Assumptions!E8))*(1-Assumptions!$B$9)-Assumptions!$B$46 -> 14651.871 | F6: =(F5*(1-Assumptions!F8))*(1-Assumptions!$B$9)-Assumptions!$B$46 -> 14962.908 | H6: =(H5*(1-Assumptions!B18))*(1-Assumptions!$B$19)-Assumptions!$B$46 -> 16928.784 | I6: =(I5*(1-Assumptions!C18))*(1-Assumptions!$B$19)-Assumptions!$B$46 -> 18326.176 | J6: =(J5*(1-Assumptions!D18))*(1-Assumptions!$B$19)-Assumptions!$B$46 -> 19553.109 | K6: =(K5*(1-Assumptions!E18))*(1-Assumptions!$B$19)-Assumptions!$B$46 -> 20751.077 | L6: =(L5*(1-Assumptions!F18))*(1-Assumptions!$B$19)-Assumptions!$B$46 -> 21725.376 | N6: =(N5*(1-Assumptions!B28))*(1-Assumptions!$B$29)-Assumptions!$B$46 -> 19542.293 | O6: =(O5*(1-Assumptions!C28))*(1-Assumptions!$B$29)-Assumptions!$B$46 -> 22217.678 | P6: =(P5*(1-Assumptions!D28))*(1-Assumptions!$B$29)-Assumptions!$B$46 -> 24668.709 | Q6: =(Q5*(1-Assumptions!E28))*(1-Assumptions!$B$29)-Assumptions!$B$46 -> 26780.383 | R6: =(R5*(1-Assumptions!F28))*(1-Assumptions!$B$29)-Assumptions!$B$46 -> 28922.394
A7: Ending common equity ($mm) | B7: =107494.6+B6-(B6*Assumptions!$B$10) -> 113357.82 | C7: =B7+C6-(C6*Assumptions!$B$10) -> 119481.57 | D7: =C7+D6-(D6*Assumptions!$B$10) -> 125937.69 | E7: =D7+E6-(E6*Assumptions!$B$10) -> 132531.03 | F7: =E7+F6-(F6*Assumptions!$B$10) -> 139264.34 | H7: =107494.6+H6-(H6*Assumptions!$B$20) -> 113419.67 | I7: =H7+I6-(I6*Assumptions!$B$20) -> 119833.84 | J7: =I7+J6-(J6*Assumptions!$B$20) -> 126677.42 | K7: =J7+K6-(K6*Assumptions!$B$20) -> 133940.3 | L7: =K7+L6-(L6*Assumptions!$B$20) -> 141544.18 | N7: =107494.6+N6-(N6*Assumptions!$B$30) -> 112380.17 | O7: =N7+O6-(O6*Assumptions!$B$30) -> 117934.59 | P7: =O7+P6-(P6*Assumptions!$B$30) -> 124101.77 | Q7: =P7+Q6-(Q6*Assumptions!$B$30) -> 130796.87 | R7: =Q7+R6-(R6*Assumptions!$B$30) -> 138027.46
A8: Ending diluted shares (mm) | B8: =300.6-(((B6*Assumptions!$B$10)*(1-Assumptions!$B$48))/((107494.6/300.6)*Assumptions!$B$47)) -> 295.55198 | C8: =B8-(((C6*Assumptions!$B$10)*(1-Assumptions!$B$48))/((B7/B8)*Assumptions!$B$47)) -> 290.63631 | D8: =C8-(((D6*Assumptions!$B$10)*(1-Assumptions!$B$48))/((C7/C8)*Assumptions!$B$47)) -> 285.80124 | E8: =D8-(((E6*Assumptions!$B$10)*(1-Assumptions!$B$48))/((D7/D8)*Assumptions!$B$47)) -> 281.19447 | F8: =E8-(((F6*Assumptions!$B$10)*(1-Assumptions!$B$48))/((E7/E8)*Assumptions!$B$47)) -> 276.79601 | H8: =300.6-(((H6*Assumptions!$B$20)*(1-Assumptions!$B$48))/((107494.6/300.6)*Assumptions!$B$47)) -> 292.84871 | I8: =H8-(((I6*Assumptions!$B$20)*(1-Assumptions!$B$48))/((H7/H8)*Assumptions!$B$47)) -> 285.10102 | J8: =I8-(((J6*Assumptions!$B$20)*(1-Assumptions!$B$48))/((I7/I8)*Assumptions!$B$47)) -> 277.48407 | K8: =J8-(((K6*Assumptions!$B$20)*(1-Assumptions!$B$48))/((J7/J8)*Assumptions!$B$47)) -> 270.04146 | L8: =K8-(((L6*Assumptions!$B$20)*(1-Assumptions!$B$48))/((K7/K8)*Assumptions!$B$47)) -> 262.8696 | N8: =300.6-(((N6*Assumptions!$B$30)*(1-Assumptions!$B$48))/((107494.6/300.6)*Assumptions!$B$47)) -> 290.27544 | O8: =N8-(((O6*Assumptions!$B$30)*(1-Assumptions!$B$48))/((N7/N8)*Assumptions!$B$47)) -> 279.43335 | P8: =O8-(((P6*Assumptions!$B$30)*(1-Assumptions!$B$48))/((O7/O8)*Assumptions!$B$47)) -> 268.39061 | Q8: =P8-(((Q6*Assumptions!$B$30)*(1-Assumptions!$B$48))/((P7/P8)*Assumptions!$B$47)) -> 257.44853 | R8: =Q8-(((R6*Assumptions!$B$30)*(1-Assumptions!$B$48))/((Q7/Q8)*Assumptions!$B$47)) -> 246.69327
A9: Diluted EPS ($) | B9: =B6/AVERAGE(300.6,B8) -> 43.711626 | C9: =C6/AVERAGE(B8,C8) -> 46.429881 | D9: =D6/AVERAGE(C8,D8) -> 49.777923 | E9: =E6/AVERAGE(D8,E8) -> 51.682475 | F9: =F6/AVERAGE(E8,F8) -> 53.63141 | H9: =H6/AVERAGE(300.6,H8) -> 57.052224 | I9: =I6/AVERAGE(H8,I8) -> 63.417888 | J9: =J6/AVERAGE(I8,J8) -> 69.511651 | K9: =K6/AVERAGE(J8,K8) -> 75.799486 | L9: =L6/AVERAGE(K8,L8) -> 81.534714 | N9: =N6/AVERAGE(300.6,N8) -> 66.146912 | O9: =O6/AVERAGE(N8,O8) -> 77.996612 | P9: =P6/AVERAGE(O8,P8) -> 90.060715 | Q9: =Q6/AVERAGE(P8,Q8) -> 101.8577 | R9: =R6/AVERAGE(Q8,R8) -> 114.73912
A10: Book value / share ($) | B10: =B7/B8 -> 383.54615 | C10: =C7/C8 -> 411.10338 | D10: =D7/D8 -> 440.64781 | E10: =E7/E8 -> 471.3145 | F10: =F7/F8 -> 503.12986 | H10: =H7/H8 -> 387.29784 | I10: =I7/I8 -> 420.32062 | J10: =J7/J8 -> 456.52143 | K10: =K7/K8 -> 495.99902 | L10: =L7/L8 -> 538.45779 | N10: =N7/N8 -> 387.15012 | O10: =O7/O8 -> 422.04909 | P10: =P7/P8 -> 462.39237 | Q10: =Q7/Q8 -> 508.05054 | R10: =R7/R8 -> 559.51046
A11: Return on average common equity (%) | B11: =B6/AVERAGE(107494.6,B7) -> 0.11799179 | C11: =C6/AVERAGE(B7,C7) -> 0.11689024 | D11: =D6/AVERAGE(C7,D7) -> 0.11691774 | E11: =E6/AVERAGE(D7,E7) -> 0.11337442 | F11: =F6/AVERAGE(E7,F7) -> 0.11010422 | H11: =H6/AVERAGE(107494.6,H7) -> 0.15326112 | I11: =I6/AVERAGE(H7,I7) -> 0.15713526 | J11: =J6/AVERAGE(I7,J7) -> 0.15863867 | K11: =K6/AVERAGE(J7,K7) -> 0.15924532 | L11: =L6/AVERAGE(K7,L7) -> 0.15772486 | N11: =N6/AVERAGE(107494.6,N7) -> 0.17775839 | O11: =O6/AVERAGE(N7,O7) -> 0.19293316 | P11: =P6/AVERAGE(O7,P7) -> 0.203843 | Q11: =Q6/AVERAGE(P7,Q7) -> 0.21012575 | R11: =R6/AVERAGE(Q7,R7) -> 0.21517691
A14: Terminal-Year (2030E) Snapshot
A15: Scenario | B15: 2030E EPS ($) | C15: 2030E BVPS ($) | D15: 2030E ROE (%) | E15: 2030E Net Revenues ($mm)
A16: Bear | B16: =F9 -> 53.63141 | C16: =F10 -> 503.12986 | D16: =F11 -> 0.11010422 | E16: =F5 -> 60591.704
A17: Base | B17: =L9 -> 81.534714 | C17: =L10 -> 538.45779 | D17: =L11 -> 0.15772486 | E17: =L5 -> 74376.646
A18: Bull | B18: =R9 -> 114.73912 | C18: =R10 -> 559.51046 | D18: =R11 -> 0.21517691 | E18: =R5 -> 86781.302
A21: This tab independently replicates the Bear/Base/Bull assumption chains from the Assumptions tab
A22: (rather than reading the single 'active' scenario used elsewhere), so all three cases can be
A23: compared side by side without toggling cell B3 on the Assumptions tab. Toggling B3 changes the
A24: single live scenario flowing through the Income Statement Proj. and Capital & Shares tabs, and the
A25: DCF / Reverse DCF workbook keys off that same selector for its base-case path.
