Workbook

Sheet Assumptions
A1: DCF Model Assumptions — Bear / Base / Bull Drivers (self-contained)
A3: ACTIVE SCENARIO (type Bear / Base / Bull): | B3: Base
A5: Bear Case drivers
A6: Fiscal Year | B6: 2026E | C6: 2027E | D6: 2028E | E6: 2029E | F6: 2030E
A7: Net revenue growth % | B7: -0.03 | C7: 0.01 | D7: 0.02 | E7: 0.02 | F7: 0.02
A8: Efficiency ratio (Opex / Revenue) | B8: 0.68 | C8: 0.67 | D8: 0.66 | E8: 0.66 | F8: 0.66
A9: Effective tax rate | B9: 0.23
A10: Total payout ratio | B10: 0.55
A11: Balance sheet / RWA growth (required equity retention) | B11: 0.02
A12: Terminal growth rate | B12: 0.02
A13: Cost of equity (CAPM) | B13: 0.115
A15: Base Case drivers
A16: Fiscal Year | B16: 2026E | C16: 2027E | D16: 2028E | E16: 2029E | F16: 2030E
A17: Net revenue growth % | B17: 0.06 | C17: 0.05 | D17: 0.05 | E17: 0.045 | F17: 0.045
A18: Efficiency ratio (Opex / Revenue) | B18: 0.63 | C18: 0.62 | D18: 0.615 | E18: 0.61 | F18: 0.61
A19: Effective tax rate | B19: 0.22
A20: Total payout ratio | B20: 0.65
A21: Balance sheet / RWA growth (required equity retention) | B21: 0.04
A22: Terminal growth rate | B22: 0.03
A23: Cost of equity (CAPM) | B23: 0.108
A25: Bull Case drivers
A26: Fiscal Year | B26: 2026E | C26: 2027E | D26: 2028E | E26: 2029E | F26: 2030E
A27: Net revenue growth % | B27: 0.11 | C27: 0.09 | D27: 0.08 | E27: 0.07 | F27: 0.065
A28: Efficiency ratio (Opex / Revenue) | B28: 0.6 | C28: 0.585 | D28: 0.575 | E28: 0.57 | F28: 0.565
A29: Effective tax rate | B29: 0.21
A30: Total payout ratio | B30: 0.75
A31: Balance sheet / RWA growth (required equity retention) | B31: 0.06
A32: Terminal growth rate | B32: 0.035
A33: Cost of equity (CAPM) | B33: 0.101
A35: CAPM Cost of Equity Build (reference)
A36: Risk-free rate (10Y UST, Jul 2 2026) | B36: 0.0448
A37: Beta (5Y monthly, approx.) | B37: 1.3
A38: Equity risk premium (long-run US) | B38: 0.05
A39: Implied cost of equity (Rf + Beta x ERP) | B39: =B36+B37*B38 -> 0.1098
A40: (Base Case Ke input above set close to this CAPM output; Bear/Bull widen
A41: the discount rate to reflect higher/lower perceived risk in each state.)
A43: ACTIVE DRIVERS (auto-selected from B3)
A44: Fiscal Year | B44: 2026E | C44: 2027E | D44: 2028E | E44: 2029E | F44: 2030E
A45: Net revenue growth % | B45: =IF($B$3="Bear",B7,IF($B$3="Base",B17,B27)) -> 0.06 | C45: =IF($B$3="Bear",C7,IF($B$3="Base",C17,C27)) -> 0.05 | D45: =IF($B$3="Bear",D7,IF($B$3="Base",D17,D27)) -> 0.05 | E45: =IF($B$3="Bear",E7,IF($B$3="Base",E17,E27)) -> 0.045 | F45: =IF($B$3="Bear",F7,IF($B$3="Base",F17,F27)) -> 0.045
A46: Efficiency ratio | B46: =IF($B$3="Bear",B8,IF($B$3="Base",B18,B28)) -> 0.63 | C46: =IF($B$3="Bear",C8,IF($B$3="Base",C18,C28)) -> 0.62 | D46: =IF($B$3="Bear",D8,IF($B$3="Base",D18,D28)) -> 0.615 | E46: =IF($B$3="Bear",E8,IF($B$3="Base",E18,E28)) -> 0.61 | F46: =IF($B$3="Bear",F8,IF($B$3="Base",F18,F28)) -> 0.61
...

Sheet FCFE Build
A1: Free Cash Flow to Equity Build (Bank FCFE method), FY2026E-FY2030E
A3: ($ in millions; active scenario per Assumptions!B3)
A4: Fiscal Year | B4: 2026E | C4: 2027E | D4: 2028E | E4: 2029E | F4: 2030E
A5: Net revenues | B5: =Assumptions!$B$60*(1+Assumptions!B45) -> 61776.8 | C5: =B5*(1+Assumptions!C45) -> 64865.64 | D5: =C5*(1+Assumptions!D45) -> 68108.922 | E5: =D5*(1+Assumptions!E45) -> 71173.823 | F5: =E5*(1+Assumptions!F45) -> 74376.646
A6: Operating expenses | B6: =B5*Assumptions!B46 -> 38919.384 | C6: =C5*Assumptions!C46 -> 40216.697 | D6: =D5*Assumptions!D46 -> 41886.987 | E6: =E5*Assumptions!E46 -> 43416.032 | F6: =F5*Assumptions!F46 -> 45369.754
A7: Pre-tax earnings | B7: =B5-B6 -> 22857.416 | C7: =C5-C6 -> 24648.943 | D7: =D5-D6 -> 26221.935 | E7: =E5-E6 -> 27757.791 | F7: =F5-F6 -> 29006.892
A8: Provision for taxes | B8: =B7*Assumptions!$B$47 -> 5028.6315 | C8: =C7*Assumptions!$B$47 -> 5422.7675 | D8: =D7*Assumptions!$B$47 -> 5768.8257 | E8: =E7*Assumptions!$B$47 -> 6106.7141 | F8: =F7*Assumptions!$B$47 -> 6381.5162
A9: Net earnings | B9: =B7-B8 -> 17828.784 | C9: =C7-C8 -> 19226.176 | D9: =D7-D8 -> 20453.109 | E9: =E7-E8 -> 21651.077 | F9: =F7-F8 -> 22625.376
A10: Less: preferred dividends | B10: =Assumptions!$B$53 -> 900 | C10: =Assumptions!$B$53 -> 900 | D10: =Assumptions!$B$53 -> 900 | E10: =Assumptions!$B$53 -> 900 | F10: =Assumptions!$B$53 -> 900
A11: Net earnings applicable to common (NIC) | B11: =B9-B10 -> 16928.784 | C11: =C9-C10 -> 18326.176 | D11: =D9-D10 -> 19553.109 | E11: =E9-E10 -> 20751.077 | F11: =F9-F10 -> 21725.376
A12: Beginning common equity | B12: =Assumptions!$B$59 -> 107494.6 | C12: =B15 -> 111794.38 | D12: =C15 -> 116266.16 | E12: =D15 -> 120916.81 | F12: =E15 -> 125753.48
A13: Required equity retention (BS/RWA growth x Beg. equity) | B13: =B12*Assumptions!$B$49 -> 4299.784 | C13: =C12*Assumptions!$B$49 -> 4471.7754 | D13: =D12*Assumptions!$B$49 -> 4650.6464 | E13: =E12*Assumptions!$B$49 -> 4836.6722 | F13: =F12*Assumptions!$B$49 -> 5030.1391
A14: Free Cash Flow to Equity (FCFE = NIC - Required retention) | B14: =B11-B13 -> 12629 | C14: =C11-C13 -> 13854.4 | D14: =D11-D13 -> 14902.463 | E14: =E11-E13 -> 15914.405 | F14: =F11-F13 -> 16695.236
A15: Ending common equity (Beg. equity + Required retention) | B15: =B12+B13 -> 111794.38 | C15: =C12+C13 -> 116266.16 | D15: =D12+D13 -> 120916.81 | E15: =E12+E13 -> 125753.48 | F15: =F12+F13 -> 130783.62
A16: Memo: implied retention ratio (Required retention / NIC) | B16: =B13/B11 -> 0.25399248 | C16: =C13/C11 -> 0.24401029 | D16: =D13/D11 -> 0.2378469 | E16: =E13/E11 -> 0.23308054 | F16: =F13/F11 -> 0.2315329
A19: Methodology (bank FCFE, per Damodaran's financial-services DCF framework): a bank cannot reinvest
A20: cash flow the way an industrial firm reinvests in capex/working capital; instead, capital is 'used'
A21: by growing risk-weighted assets, which requires retaining common equity to hold leverage/CET1 ratios
A22: roughly constant. FCFE = Net income to common - (required capital retention to fund that growth) =
A23: the maximum a bank can safely return to shareholders via dividends + buybacks without eroding capital.

Sheet DCF Valuation
A1: DCF Valuation — Present Value of FCFE + Terminal Value
A3: ($ in millions, except per share; active scenario per Assumptions!B3)
A4: Fiscal Year | B4: 2026E | C4: 2027E | D4: 2028E | E4: 2029E | F4: 2030E
A5: Discount period (t) | B5: 1 | C5: 2 | D5: 3 | E5: 4 | F5: 5
A6: FCFE [linked from FCFE Build] | B6: ='FCFE Build'!B14 -> 12629 | C6: ='FCFE Build'!C14 -> 13854.4 | D6: ='FCFE Build'!D14 -> 14902.463 | E6: ='FCFE Build'!E14 -> 15914.405 | F6: ='FCFE Build'!F14 -> 16695.236
A7: Discount factor @ active Ke | B7: =1/(1+Assumptions!$B$51)^B5 -> 0.90252708 | C7: =1/(1+Assumptions!$B$51)^C5 -> 0.81455512 | D7: =1/(1+Assumptions!$B$51)^D5 -> 0.73515805 | E7: =1/(1+Assumptions!$B$51)^E5 -> 0.66350005 | F7: =1/(1+Assumptions!$B$51)^F5 -> 0.59882676
A8: PV of FCFE | B8: =B6*B7 -> 11398.015 | C8: =C6*C7 -> 11285.173 | D8: =D6*D7 -> 10955.666 | E8: =E6*E7 -> 10559.208 | F8: =F6*F7 -> 9997.5543
A10: Valuation Summary
A11: Sum of PV of explicit-period FCFE (2026E-2030E) | B11: =SUM(B8:F8) -> 54195.616
A12: Terminal value at end of 2030E (Gordon growth) | B12: =F6*(1+Assumptions!$B$50)/(Assumptions!$B$51-Assumptions!$B$50) -> 220462.74
A13: PV of terminal value | B13: =B12*F7 -> 132018.99
A14: Terminal value as % of total equity value | B14: =B13/B15 -> 0.70896151
A15: Implied Equity Value ($mm) | B15: =B11+B13 -> 186214.6
A16: / Current diluted shares outstanding (mm) | B16: =Assumptions!$B$57 -> 295
A17: Implied Value per Share ($) | B17: =B15/B16 -> 631.23594
A18: Current share price ($) | B18: =Assumptions!$B$56 -> 1022.11
A19: Implied upside / (downside) vs. current price | B19: =B17/B18-1 -> -0.38241878
A22: Read this alongside the Reverse DCF tab: this sheet asks 'what is GS worth given my assumptions?'
A23: The Reverse DCF tab asks the opposite and arguably more useful question for a stock trading near
A24: highs: 'what does the CURRENT price already assume, and is that assumption reasonable?'

Sheet Reverse DCF
A1: Reverse DCF — What Growth Does the Current Price Already Assume?
A3: Single-stage (Gordon growth) closed-form solve
A4: Implied current market equity value ($mm) | B4: =Assumptions!$B$58 -> 301522.45
A5: Next-year FCFE, 2026E ($mm) [linked, base case] | B5: ='DCF Valuation'!B6 -> 12629
A6: Cost of equity, Ke (active scenario) | B6: =Assumptions!$B$51 -> 0.108
A7: Implied FCFE yield (FCFE1 / Market equity value) | B7: =B5/B4 -> 0.041884113
A8: Implied perpetual FCFE growth rate priced in, g* = Ke - Yield | B8: =B6-B7 -> 0.066115887
A10: Formula: Single-stage Gordon Growth says Price = FCFE1 / (Ke - g). Solving for g given the current
A11: price is algebra: g* = Ke - FCFE1/Price. This is the market-implied 'what has to be true forever'
A12: growth rate. Compare it to (a) GS's own 5-yr revenue CAGR history and (b) nominal US GDP growth
A13: (~4-5%) as sanity checks -- a g* persistently above long-run GDP growth is a classic red flag that
A14: a stock is priced for perfection.
A16: Implied growth rate g*, sensitized across cost-of-equity assumptions
A17: Cost of equity (Ke) | B17: 0.085 | C17: 0.095 | D17: 0.105 | E17: 0.115 | F17: 0.125 | G17: 0.135
A18: Implied g* (this scenario FCFE1, this Ke) | B18: =B17-$B$5/$B$4 -> 0.043115887 | C18: =C17-$B$5/$B$4 -> 0.053115887 | D18: =D17-$B$5/$B$4 -> 0.063115887 | E18: =E17-$B$5/$B$4 -> 0.073115887 | F18: =F17-$B$5/$B$4 -> 0.083115887 | G18: =G17-$B$5/$B$4 -> 0.093115887
A20: Sanity check: translating g* into required ROE (sustainable growth identity)
A21: Sustainable growth identity: g = ROE x Retention ratio
A22: Assumed retention ratio (1 - payout), Base Case | B22: =1-Assumptions!$B$20 -> 0.35
A23: Required ROE to sustain g* at this retention ratio (g* / retention) | B23: =B8/B22 -> 0.18890253
A24: For reference: GS FY2025A ROE was 15.0%; FY2021 cyclical-peak ROE was 23.0%
A26: Reading the result: if the required ROE above is comfortably inside GS's own historical range
A27: (7.5% trough in 2023, 23.0% cyclical peak in 2021, 15.0% most recent), the current price is pricing
A28: in a plausible-but-optimistic continuation of the current up-cycle. If it is ABOVE the 2021 peak,
A29: the market is pricing in a structurally higher through-cycle ROE than GS has ever historically
A30: sustained -- a meaningfully more aggressive assumption than the Bull Case in this model.

Sheet Sensitivity Tables
A1: Sensitivity Analysis — Implied Value per Share ($)
A3: 2-Way: Implied share price by Cost of Equity (rows) x Terminal Growth Rate (columns)
A5: Ke \ g | B5: 0.015 | C5: 0.02 | D5: 0.025 | E5: 0.03 | F5: 0.035 | G5: 0.04
A6: 0.085 | B6: =(SUMPRODUCT('FCFE Build'!$B$14:$F$14/(1+$A6)^'DCF Valuation'!$B$5:$F$5)+(('FCFE Build'!$F$14*(1+B$5))/($A6-B$5))/(1+$A6)^5)/Assumptions!$B$57 -> 741.20988 | C6: =(SUMPRODUCT('FCFE Build'!$B$14:$F$14/(1+$A6)^'DCF Valuation'!$B$5:$F$5)+(('FCFE Build'!$F$14*(1+C$5))/($A6-C$5))/(1+$A6)^5)/Assumptions!$B$57 -> 786.08547 | D6: =(SUMPRODUCT('FCFE Build'!$B$14:$F$14/(1+$A6)^'DCF Valuation'!$B$5:$F$5)+(('FCFE Build'!$F$14*(1+D$5))/($A6-D$5))/(1+$A6)^5)/Assumptions!$B$57 -> 838.44033 | E6: =(SUMPRODUCT('FCFE Build'!$B$14:$F$14/(1+$A6)^'DCF Valuation'!$B$5:$F$5)+(('FCFE Build'!$F$14*(1+E$5))/($A6-E$5))/(1+$A6)^5)/Assumptions!$B$57 -> 900.31426 | F6: =(SUMPRODUCT('FCFE Build'!$B$14:$F$14/(1+$A6)^'DCF Valuation'!$B$5:$F$5)+(('FCFE Build'!$F$14*(1+F$5))/($A6-F$5))/(1+$A6)^5)/Assumptions!$B$57 -> 974.56297 | G6: =(SUMPRODUCT('FCFE Build'!$B$14:$F$14/(1+$A6)^'DCF Valuation'!$B$5:$F$5)+(('FCFE Build'!$F$14*(1+G$5))/($A6-G$5))/(1+$A6)^5)/Assumptions!$B$57 -> 1065.3114
A7: 0.095 | B7: =(SUMPRODUCT('FCFE Build'!$B$14:$F$14/(1+$A7)^'DCF Valuation'!$B$5:$F$5)+(('FCFE Build'!$F$14*(1+B$5))/($A7-B$5))/(1+$A7)^5)/Assumptions!$B$57 -> 646.332 | C7: =(SUMPRODUCT('FCFE Build'!$B$14:$F$14/(1+$A7)^'DCF Valuation'!$B$5:$F$5)+(('FCFE Build'!$F$14*(1+C$5))/($A7-C$5))/(1+$A7)^5)/Assumptions!$B$57 -> 679.13646 | D7: =(SUMPRODUCT('FCFE Build'!$B$14:$F$14/(1+$A7)^'DCF Valuation'!$B$5:$F$5)+(('FCFE Build'!$F$14*(1+D$5))/($A7-D$5))/(1+$A7)^5)/Assumptions!$B$57 -> 716.62727 | E7: =(SUMPRODUCT('FCFE Build'!$B$14:$F$14/(1+$A7)^'DCF Valuation'!$B$5:$F$5)+(('FCFE Build'!$F$14*(1+E$5))/($A7-E$5))/(1+$A7)^5)/Assumptions!$B$57 -> 759.88589 | F7: =(SUMPRODUCT('FCFE Build'!$B$14:$F$14/(1+$A7)^'DCF Valuation'!$B$5:$F$5)+(('FCFE Build'!$F$14*(1+F$5))/($A7-F$5))/(1+$A7)^5)/Assumptions!$B$57 -> 810.35428 | G7: =(SUMPRODUCT('FCFE Build'!$B$14:$F$14/(1+$A7)^'DCF Valuation'!$B$5:$F$5)+(('FCFE Build'!$F$14*(1+G$5))/($A7-G$5))/(1+$A7)^5)/Assumptions!$B$57 -> 869.99875
A8: 0.105 | B8: =(SUMPRODUCT('FCFE Build'!$B$14:$F$14/(1+$A8)^'DCF Valuation'!$B$5:$F$5)+(('FCFE Build'!$F$14*(1+B$5))/($A8-B$5))/(1+$A8)^5)/Assumptions!$B$57 -> 572.60359 | C8: =(SUMPRODUCT('FCFE Build'!$B$14:$F$14/(1+$A8)^'DCF Valuation'!$B$5:$F$5)+(('FCFE Build'!$F$14*(1+C$5))/($A8-C$5))/(1+$A8)^5)/Assumptions!$B$57 -> 597.41378 | D8: =(SUMPRODUCT('FCFE Build'!$B$14:$F$14/(1+$A8)^'DCF Valuation'!$B$5:$F$5)+(('FCFE Build'!$F$14*(1+D$5))/($A8-D$5))/(1+$A8)^5)/Assumptions!$B$57 -> 625.32524 | E8: =(SUMPRODUCT('FCFE Build'!$B$14:$F$14/(1+$A8)^'DCF Valuation'!$B$5:$F$5)+(('FCFE Build'!$F$14*(1+E$5))/($A8-E$5))/(1+$A8)^5)/Assumptions!$B$57 -> 656.95823 | F8: =(SUMPRODUCT('FCFE Build'!$B$14:$F$14/(1+$A8)^'DCF Valuation'!$B$5:$F$5)+(('FCFE Build'!$F$14*(1+F$5))/($A8-F$5))/(1+$A8)^5)/Assumptions!$B$57 -> 693.11021 | G8: =(SUMPRODUCT('FCFE Build'!$B$14:$F$14/(1+$A8)^'DCF Valuation'!$B$5:$F$5)+(('FCFE Build'!$F$14*(1+G$5))/($A8-G$5))/(1+$A8)^5)/Assumptions!$B$57 -> 734.82404
A9: 0.108 | B9: =(SUMPRODUCT('FCFE Build'!$B$14:$F$14/(1+$A9)^'DCF Valuation'!$B$5:$F$5)+(('FCFE Build'!$F$14*(1+B$5))/($A9-B$5))/(1+$A9)^5)/Assumptions!$B$57 -> 553.58884 | C9: =(SUMPRODUCT('FCFE Build'!$B$14:$F$14/(1+$A9)^'DCF Valuation'!$B$5:$F$5)+(('FCFE Build'!$F$14*(1+C$5))/($A9-C$5))/(1+$A9)^5)/Assumptions!$B$57 -> 576.53003 | D9: =(SUMPRODUCT('FCFE Build'!$B$14:$F$14/(1+$A9)^'DCF Valuation'!$B$5:$F$5)+(('FCFE Build'!$F$14*(1+D$5))/($A9-D$5))/(1+$A9)^5)/Assumptions!$B$57 -> 602.23522 | E9: =(SUMPRODUCT('FCFE Build'!$B$14:$F$14/(1+$A9)^'DCF Valuation'!$B$5:$F$5)+(('FCFE Build'!$F$14*(1+E$5))/($A9-E$5))/(1+$A9)^5)/Assumptions!$B$57 -> 631.23594 | F9: =(SUMPRODUCT('FCFE Build'!$B$14:$F$14/(1+$A9)^'DCF Valuation'!$B$5:$F$5)+(('FCFE Build'!$F$14*(1+F$5))/($A9-F$5))/(1+$A9)^5)/Assumptions!$B$57 -> 664.20937 | G9: =(SUMPRODUCT('FCFE Build'!$B$14:$F$14/(1+$A9)^'DCF Valuation'!$B$5:$F$5)+(('FCFE Build'!$F$14*(1+G$5))/($A9-G$5))/(1+$A9)^5)/Assumptions!$B$57 -> 702.03182
A10: 0.115 | B10: =(SUMPRODUCT('FCFE Build'!$B$14:$F$14/(1+$A10)^'DCF Valuation'!$B$5:$F$5)+(('FCFE Build'!$F$14*(1+B$5))/($A10-B$5))/(1+$A10)^5)/Assumptions!$B$57 -> 513.6772 | C10: =(SUMPRODUCT('FCFE Build'!$B$14:$F$14/(1+$A10)^'DCF Valuation'!$B$5:$F$5)+(('FCFE Build'!$F$14*(1+C$5))/($A10-C$5))/(1+$A10)^5)/Assumptions!$B$57 -> 532.94879 | D10: =(SUMPRODUCT('FCFE Build'!$B$14:$F$14/(1+$A10)^'DCF Valuation'!$B$5:$F$5)+(('FCFE Build'!$F$14*(1+D$5))/($A10-D$5))/(1+$A10)^5)/Assumptions!$B$57 -> 554.36166 | E10: =(SUMPRODUCT('FCFE Build'!$B$14:$F$14/(1+$A10)^'DCF Valuation'!$B$5:$F$5)+(('FCFE Build'!$F$14*(1+E$5))/($A10-E$5))/(1+$A10)^5)/Assumptions!$B$57 -> 578.2937 | F10: =(SUMPRODUCT('FCFE Build'!$B$14:$F$14/(1+$A10)^'DCF Valuation'!$B$5:$F$5)+(('FCFE Build'!$F$14*(1+F$5))/($A10-F$5))/(1+$A10)^5)/Assumptions!$B$57 -> 605.21724 | G10: =(SUMPRODUCT('FCFE Build'!$B$14:$F$14/(1+$A10)^'DCF Valuation'!$B$5:$F$5)+(('FCFE Build'!$F$14*(1+G$5))/($A10-G$5))/(1+$A10)^5)/Assumptions!$B$57 -> 635.73059
A11: 0.125 | B11: =(SUMPRODUCT('FCFE Build'!$B$14:$F$14/(1+$A11)^'DCF Valuation'!$B$5:$F$5)+(('FCFE Build'!$F$14*(1+B$5))/($A11-B$5))/(1+$A11)^5)/Assumptions!$B$57 -> 465.51367 | C11: =(SUMPRODUCT('FCFE Build'!$B$14:$F$14/(1+$A11)^'DCF Valuation'!$B$5:$F$5)+(('FCFE Build'!$F$14*(1+C$5))/($A11-C$5))/(1+$A11)^5)/Assumptions!$B$57 -> 480.80864 | D11: =(SUMPRODUCT('FCFE Build'!$B$14:$F$14/(1+$A11)^'DCF Valuation'!$B$5:$F$5)+(('FCFE Build'!$F$14*(1+D$5))/($A11-D$5))/(1+$A11)^5)/Assumptions!$B$57 -> 497.6331 | E11: =(SUMPRODUCT('FCFE Build'!$B$14:$F$14/(1+$A11)^'DCF Valuation'!$B$5:$F$5)+(('FCFE Build'!$F$14*(1+E$5))/($A11-E$5))/(1+$A11)^5)/Assumptions!$B$57 -> 516.22856 | F11: =(SUMPRODUCT('FCFE Build'!$B$14:$F$14/(1+$A11)^'DCF Valuation'!$B$5:$F$5)+(('FCFE Build'!$F$14*(1+F$5))/($A11-F$5))/(1+$A11)^5)/Assumptions!$B$57 -> 536.89018 | G11: =(SUMPRODUCT('FCFE Build'!$B$14:$F$14/(1+$A11)^'DCF Valuation'!$B$5:$F$5)+(('FCFE Build'!$F$14*(1+G$5))/($A11-G$5))/(1+$A11)^5)/Assumptions!$B$57 -> 559.98258
A13: Current share price for reference: $1,022.11 (highlight cells above/below this manually or eyeball vs. green/red shading)
A15: One-Way Sensitivities (Base Case, holding other drivers constant)
A16: Terminal growth rate (Ke held at 10.8% base case)
B17: 0.015 | C17: 0.02 | D17: 0.025 | E17: 0.03 | F17: 0.035 | G17: 0.04
A18: Implied value / share ($) | B18: =(SUMPRODUCT('FCFE Build'!$B$14:$F$14/(1.108)^'DCF Valuation'!$B$5:$F$5)+(('FCFE Build'!$F$14*(1+B17))/(0.108-B17))/(1.108)^5)/Assumptions!$B$57 -> 553.58884 | C18: =(SUMPRODUCT('FCFE Build'!$B$14:$F$14/(1.108)^'DCF Valuation'!$B$5:$F$5)+(('FCFE Build'!$F$14*(1+C17))/(0.108-C17))/(1.108)^5)/Assumptions!$B$57 -> 576.53003 | D18: =(SUMPRODUCT('FCFE Build'!$B$14:$F$14/(1.108)^'DCF Valuation'!$B$5:$F$5)+(('FCFE Build'!$F$14*(1+D17))/(0.108-D17))/(1.108)^5)/Assumptions!$B$57 -> 602.23522 | E18: =(SUMPRODUCT('FCFE Build'!$B$14:$F$14/(1.108)^'DCF Valuation'!$B$5:$F$5)+(('FCFE Build'!$F$14*(1+E17))/(0.108-E17))/(1.108)^5)/Assumptions!$B$57 -> 631.23594 | F18: =(SUMPRODUCT('FCFE Build'!$B$14:$F$14/(1.108)^'DCF Valuation'!$B$5:$F$5)+(('FCFE Build'!$F$14*(1+F17))/(0.108-F17))/(1.108)^5)/Assumptions!$B$57 -> 664.20937 | G18: =(SUMPRODUCT('FCFE Build'!$B$14:$F$14/(1.108)^'DCF Valuation'!$B$5:$F$5)+(('FCFE Build'!$F$14*(1+G17))/(0.108-G17))/(1.108)^5)/Assumptions!$B$57 -> 702.03182
A20: Cost of equity (terminal growth held at 3.0% base case)
B21: 0.085 | C21: 0.095 | D21: 0.105 | E21: 0.115 | F21: 0.125 | G21: 0.135
A22: Implied value / share ($) | B22: =(SUMPRODUCT('FCFE Build'!$B$14:$F$14/(1+B21)^'DCF Valuation'!$B$5:$F$5)+(('FCFE Build'!$F$14*1.03)/(B21-0.03))/(1+B21)^5)/Assumptions!$B$57 -> 900.31426 | C22: =(SUMPRODUCT('FCFE Build'!$B$14:$F$14/(1+C21)^'DCF Valuation'!$B$5:$F$5)+(('FCFE Build'!$F$14*1.03)/(C21-0.03))/(1+C21)^5)/Assumptions!$B$57 -> 759.88589 | D22: =(SUMPRODUCT('FCFE Build'!$B$14:$F$14/(1+D21)^'DCF Valuation'!$B$5:$F$5)+(('FCFE Build'!$F$14*1.03)/(D21-0.03))/(1+D21)^5)/Assumptions!$B$57 -> 656.95823 | E22: =(SUMPRODUCT('FCFE Build'!$B$14:$F$14/(1+E21)^'DCF Valuation'!$B$5:$F$5)+(('FCFE Build'!$F$14*1.03)/(E21-0.03))/(1+E21)^5)/Assumptions!$B$57 -> 578.2937 | F22: =(SUMPRODUCT('FCFE Build'!$B$14:$F$14/(1+F21)^'DCF Valuation'!$B$5:$F$5)+(('FCFE Build'!$F$14*1.03)/(F21-0.03))/(1+F21)^5)/Assumptions!$B$57 -> 516.22856 | G22: =(SUMPRODUCT('FCFE Build'!$B$14:$F$14/(1+G21)^'DCF Valuation'!$B$5:$F$5)+(('FCFE Build'!$F$14*1.03)/(G21-0.03))/(1+G21)^5)/Assumptions!$B$57 -> 466.01865
A24: Reading the grid: at the Base Case (Ke=10.8%, g=3.0%), implied value/share sits well below the
A25: current market price -- consistent with the Reverse DCF finding that the market is pricing in a
A26: higher sustainable growth/ROE than this model's Base Case assumes. Use the grid to see how much
A27: Ke would need to compress (or g rise) to justify the current price -- that combination is the real
A28: underwriting question for anyone buying GS at today's level.

Sheet Scenario Valuation
A1: Bull / Base / Bear — Independent DCF Valuation Comparison
B3: Bear Case | H3: Base Case | N3: Bull Case
B4: 2026E | C4: 2027E | D4: 2028E | E4: 2029E | F4: 2030E | H4: 2026E | I4: 2027E | J4: 2028E | K4: 2029E | L4: 2030E | N4: 2026E | O4: 2027E | P4: 2028E | Q4: 2029E | R4: 2030E
A6: Net revenues ($mm) | B6: =Assumptions!$B$60*(1+Assumptions!B7) -> 56531.6 | C6: =B6*(1+Assumptions!C7) -> 57096.916 | D6: =C6*(1+Assumptions!D7) -> 58238.854 | E6: =D6*(1+Assumptions!E7) -> 59403.631 | F6: =E6*(1+Assumptions!F7) -> 60591.704 | H6: =Assumptions!$B$60*(1+Assumptions!B17) -> 61776.8 | I6: =H6*(1+Assumptions!C17) -> 64865.64 | J6: =I6*(1+Assumptions!D17) -> 68108.922 | K6: =J6*(1+Assumptions!E17) -> 71173.823 | L6: =K6*(1+Assumptions!F17) -> 74376.646 | N6: =Assumptions!$B$60*(1+Assumptions!B27) -> 64690.8 | O6: =N6*(1+Assumptions!C27) -> 70512.972 | P6: =O6*(1+Assumptions!D27) -> 76154.01 | Q6: =P6*(1+Assumptions!E27) -> 81484.79 | R6: =Q6*(1+Assumptions!F27) -> 86781.302
A7: Net earnings to common ($mm) | B7: =(B6*(1-Assumptions!B8))*(1-Assumptions!$B$9)-Assumptions!$B$53 -> 13029.386 | C7: =(C6*(1-Assumptions!C8))*(1-Assumptions!$B$9)-Assumptions!$B$53 -> 13608.326 | D7: =(D6*(1-Assumptions!D8))*(1-Assumptions!$B$9)-Assumptions!$B$53 -> 14346.932 | E7: =(E6*(1-Assumptions!E8))*(1-Assumptions!$B$9)-Assumptions!$B$53 -> 14651.871 | F7: =(F6*(1-Assumptions!F8))*(1-Assumptions!$B$9)-Assumptions!$B$53 -> 14962.908 | H7: =(H6*(1-Assumptions!B18))*(1-Assumptions!$B$19)-Assumptions!$B$53 -> 16928.784 | I7: =(I6*(1-Assumptions!C18))*(1-Assumptions!$B$19)-Assumptions!$B$53 -> 18326.176 | J7: =(J6*(1-Assumptions!D18))*(1-Assumptions!$B$19)-Assumptions!$B$53 -> 19553.109 | K7: =(K6*(1-Assumptions!E18))*(1-Assumptions!$B$19)-Assumptions!$B$53 -> 20751.077 | L7: =(L6*(1-Assumptions!F18))*(1-Assumptions!$B$19)-Assumptions!$B$53 -> 21725.376 | N7: =(N6*(1-Assumptions!B28))*(1-Assumptions!$B$29)-Assumptions!$B$53 -> 19542.293 | O7: =(O6*(1-Assumptions!C28))*(1-Assumptions!$B$29)-Assumptions!$B$53 -> 22217.678 | P7: =(P6*(1-Assumptions!D28))*(1-Assumptions!$B$29)-Assumptions!$B$53 -> 24668.709 | Q7: =(Q6*(1-Assumptions!E28))*(1-Assumptions!$B$29)-Assumptions!$B$53 -> 26780.383 | R7: =(R6*(1-Assumptions!F28))*(1-Assumptions!$B$29)-Assumptions!$B$53 -> 28922.394
A8: Beginning common equity ($mm) | B8: =Assumptions!$B$59 -> 107494.6 | C8: =B8*(1+Assumptions!$B$11) -> 109644.49 | D8: =C8*(1+Assumptions!$B$11) -> 111837.38 | E8: =D8*(1+Assumptions!$B$11) -> 114074.13 | F8: =E8*(1+Assumptions!$B$11) -> 116355.61 | H8: =Assumptions!$B$59 -> 107494.6 | I8: =H8*(1+Assumptions!$B$21) -> 111794.38 | J8: =I8*(1+Assumptions!$B$21) -> 116266.16 | K8: =J8*(1+Assumptions!$B$21) -> 120916.81 | L8: =K8*(1+Assumptions!$B$21) -> 125753.48 | N8: =Assumptions!$B$59 -> 107494.6 | O8: =N8*(1+Assumptions!$B$31) -> 113944.28 | P8: =O8*(1+Assumptions!$B$31) -> 120780.93 | Q8: =P8*(1+Assumptions!$B$31) -> 128027.79 | R8: =Q8*(1+Assumptions!$B$31) -> 135709.46
A9: Required equity retention ($mm) | B9: =B8*Assumptions!$B$11 -> 2149.892 | C9: =C8*Assumptions!$B$11 -> 2192.8898 | D9: =D8*Assumptions!$B$11 -> 2236.7476 | E9: =E8*Assumptions!$B$11 -> 2281.4826 | F9: =F8*Assumptions!$B$11 -> 2327.1122 | H9: =H8*Assumptions!$B$21 -> 4299.784 | I9: =I8*Assumptions!$B$21 -> 4471.7754 | J9: =J8*Assumptions!$B$21 -> 4650.6464 | K9: =K8*Assumptions!$B$21 -> 4836.6722 | L9: =L8*Assumptions!$B$21 -> 5030.1391 | N9: =N8*Assumptions!$B$31 -> 6449.676 | O9: =O8*Assumptions!$B$31 -> 6836.6566 | P9: =P8*Assumptions!$B$31 -> 7246.856 | Q9: =Q8*Assumptions!$B$31 -> 7681.6673 | R9: =R8*Assumptions!$B$31 -> 8142.5673
A10: FCFE ($mm) | B10: =B7-B9 -> 10879.494 | C10: =C7-C9 -> 11415.437 | D10: =D7-D9 -> 12110.184 | E10: =E7-E9 -> 12370.388 | F10: =F7-F9 -> 12635.796 | H10: =H7-H9 -> 12629 | I10: =I7-I9 -> 13854.4 | J10: =J7-J9 -> 14902.463 | K10: =K7-K9 -> 15914.405 | L10: =L7-L9 -> 16695.236 | N10: =N7-N9 -> 13092.617 | O10: =O7-O9 -> 15381.021 | P10: =P7-P9 -> 17421.853 | Q10: =Q7-Q9 -> 19098.716 | R10: =R7-R9 -> 20779.827
A11: Discount factor | B11: =1/(1+Assumptions!$B$13)^1 -> 0.89686099 | C11: =1/(1+Assumptions!$B$13)^2 -> 0.80435963 | D11: =1/(1+Assumptions!$B$13)^3 -> 0.72139877 | E11: =1/(1+Assumptions!$B$13)^4 -> 0.64699441 | F11: =1/(1+Assumptions!$B$13)^5 -> 0.58026405 | H11: =1/(1+Assumptions!$B$23)^1 -> 0.90252708 | I11: =1/(1+Assumptions!$B$23)^2 -> 0.81455512 | J11: =1/(1+Assumptions!$B$23)^3 -> 0.73515805 | K11: =1/(1+Assumptions!$B$23)^4 -> 0.66350005 | L11: =1/(1+Assumptions!$B$23)^5 -> 0.59882676 | N11: =1/(1+Assumptions!$B$33)^1 -> 0.90826521 | O11: =1/(1+Assumptions!$B$33)^2 -> 0.8249457 | P11: =1/(1+Assumptions!$B$33)^3 -> 0.74926948 | Q11: =1/(1+Assumptions!$B$33)^4 -> 0.6805354 | R11: =1/(1+Assumptions!$B$33)^5 -> 0.61810663
A12: PV of FCFE ($mm) | B12: =B10*B11 -> 9757.3939 | C12: =C10*C11 -> 9182.1163 | D12: =D10*D11 -> 8736.2722 | E12: =E10*E11 -> 8003.572 | F12: =F10*F11 -> 7332.0981 | H12: =H10*H11 -> 11398.015 | I12: =I10*I11 -> 11285.173 | J12: =J10*J11 -> 10955.666 | K12: =K10*K11 -> 10559.208 | L12: =L10*L11 -> 9997.5543 | N12: =N10*N11 -> 11891.568 | O12: =O10*O11 -> 12688.507 | P12: =P10*P11 -> 13053.663 | Q12: =Q10*Q11 -> 12997.352 | R12: =R10*R11 -> 12844.149
A15: Valuation Output
A16: Scenario | B16: Sum PV explicit FCFE ($mm) | C16: Terminal value, undiscounted ($mm) | D16: PV of terminal value ($mm) | E16: Implied Equity Value ($mm) | F16: Implied Value / Share ($) | G16: vs. Current Price
A17: Bear | B17: =SUM(B12:F12) -> 43011.452 | C17: =F10*(1+Assumptions!$B$12)/(Assumptions!$B$13-Assumptions!$B$12) -> 135668.55 | D17: =C17*F11 -> 78723.579 | E17: =B17+D17 -> 121735.03 | F17: =E17/Assumptions!$B$57 -> 412.66112 | G17: =F17/Assumptions!$B$56-1 -> -0.59626545
A18: Base | B18: =SUM(H12:L12) -> 54195.616 | C18: =L10*(1+Assumptions!$B$22)/(Assumptions!$B$23-Assumptions!$B$22) -> 220462.74 | D18: =C18*L11 -> 132018.99 | E18: =B18+D18 -> 186214.6 | F18: =E18/Assumptions!$B$57 -> 631.23594 | G18: =F18/Assumptions!$B$56-1 -> -0.38241878
A19: Bull | B19: =SUM(N12:R12) -> 63475.24 | C19: =R10*(1+Assumptions!$B$32)/(Assumptions!$B$33-Assumptions!$B$32) -> 325865.47 | D19: =C19*R11 -> 201419.61 | E19: =B19+D19 -> 264894.85 | F19: =E19/Assumptions!$B$57 -> 897.94864 | G19: =F19/Assumptions!$B$56-1 -> -0.12147554
A22: Each scenario uses its own revenue growth, efficiency ratio, tax rate, balance-sheet growth,
A23: terminal growth AND cost of equity (wider discount rate in Bear to reflect higher perceived risk,
A24: tighter in Bull) -- consistent with how sell-side scenario analysis typically treats risk, not just
A25: growth. This is a fully independent recompute per scenario, not a simple +/- shock to the Base Case.

Sheet Data Sources
A1: Data Sources & Key Methodology Notes
A3: Historical financials (2025A base year) | B3: GS FY2025 10-K / 4Q25 Earnings Release, Jan 15 2026, SEC EDGAR
A4: Current share price, shares outstanding | B4: Robinhood + Google Finance GS:NYSE snapshot, ~Jul 2, 2026
A5: 10Y Treasury / risk-free rate | B5: Trading Economics / MacroMicro, Jul 2, 2026 (4.48%)
A6: Beta | B6: Google Finance, ~Jul 2026 (1.30, 5Y monthly approx.)
A7: Equity risk premium | B7: Standard long-run US ERP assumption (5.0%), Damodaran-style convention
A8: Bear/Base/Bull driver assumptions | B8: Analyst-constructed for this project, calibrated to GS 2021-2025 historical range (see Historical Financial Analysis workbook) and current sell-side consensus growth/margin ranges for large-cap US banks; NOT sourced from a specific bank research report
A9: FCFE / bank DCF methodology | B9: Aswath Damodaran's financial-services DCF framework (FCFE = Net income to common - required equity retention to fund balance-sheet/RWA growth); see damodaran.com 'Valuing Financial Service Firms'
A10: Reverse DCF methodology | B10: Single-stage Gordon Growth algebraic inversion (g* = Ke - FCFE1/Price); standard reverse-DCF technique used in equity research
A12: DISCLAIMER: Portfolio / educational project, not investment research or advice. Verify all inputs against primary sources before relying on this model for any real decision.
